Workbook

Sheet README
A1: 집안 이동 시각화 엑셀 템플릿 (1분=1행)
A3: 1) RawData 시트에 'Date, MinuteIdx(0~1439), LocHex, Distance_m' 4개 열만 붙여넣으세요. (B~E열)
A4: 2) RawData의 A열(Key)과 F열(Hour)은 자동 계산 열입니다. 붙여넣기/수정하지 마세요.
A5: 3) DailyView 시트의 B3에 날짜를 입력하면 대시보드가 자동 갱신됩니다.
A6: 4) 방 이동 횟수/정확한 조회를 위해 RawData는 Date 오름차순, MinuteIdx 오름차순으로 정렬 권장
A8: LocHex 코드 예: 00(침실A), 01(침실B), 0A(거실A), 14(화장실), 1E(주방), FE(외출)

Sheet Mapping
A1: 코드 매핑
A3: LocHex | B3: LocName | C3: LegendColor
A4: 00 | B4: 침실A
A5: 01 | B5: 침실B
A6: 0A | B6: 거실A
A7: 14 | B7: 화장실
A8: 1E | B8: 주방
A9: FE | B9: 외출

Sheet RawData
A1: Key | B1: Date | C1: MinuteIdx | D1: LocHex | E1: Distance_m | F1: Hour | G1: LocHex_norm | I1: 140000000101010101010000000101010101010101010101010101011E0001010101011E0101010A000101010101010101010101010101010101010101010101010101010101010101010101010101010101010101010101000101000000000000000001141E010014140000000A01000001010101010100010101010101010101010101010001010101010101010101000A00000000000000000000000000000000000000000000000000000000000000000000000000000000000000000000000000000000000000000000000000000000000000000000000000000000000000000000000000000000000000000000000000000000000000000000000000000000000000000000000000000000000000000000000000000000000000000000000000000000000000000000000000000000000000000000000000000000000000000000000000000000000000000000000000000000000000000000000000000000000000000000000000000000000000000000000000000000000000000000000000000000000000000000000000000000000000000000000000000000000000000000000000000000000000000000000000000000000000000000000000000000000000000000000000000000000000000000000000000000000000000000000000000000000000000000000000000000000000000000000000000000000000000000000000000000000000000000000000000000000000000000000000000000000000000000000000000000000000000000000000000A1E141414141414141414141414141400001E00001414141414141414141414141E0000000000000000000A1E1E0A0A0A0A0A0A0A0A0A0A0A01001E1E0A0A0A0A0A0AFEFEFEFEFEFEFEFEFEFEFEFEFEFEFEFEFEFEFEFEFEFEFEFEFEFEFEFEFEFEFEFEFEFEFEFEFEFEFEFEFEFEFEFEFEFEFEFEFEFEFEFEFEFEFEFEFEFEFEFEFEFEFEFEFEFEFEFEFEFEFEFEFEFEFEFEFEFEFEFEFEFEFEFEFEFEFEFEFEFEFEFEFEFEFEFEFEFEFEFEFEFEFEFEFEFEFEFEFEFEFEFEFEFEFEFEFEFEFEFEFE140A1E1E1E1E1E1E1E0A1E1E0A0A0A1E1E0A0A0A0A0A1E0A0A1E1E0A0A0A0A0A0A0A1E1E0A0A0A0A1E1E0A0A1E1E1E1E1E1E1E1E1E1E1E1E1E1E1E1E1E1E1E1E1E1E1E1E1E1E1E1E1E1E1E1E1E1E1E1E1E1E1E1E1E1E0A1E1E1E0A0A0A0A0A1E1E1E1E1E1E1E1E141E0A0A0A0A0A0A1E1E1E1E1E1E1E1E1E1E1E1E1414141414141414141414140A14141E0A0A0A0A0A0A0A0A0A0A0A0A1E0A0A0A0A1E0000001E1E1E1E1E1E1E1E1E1E1E1E1E1E1E1E1E001E0000000000000000000000000000000000000000000000000000000000001E0000000000000000001E0A0A0A1E1E1E1E0A0A0A0A0A0A0A141E1E0A0A0AFEFEFE0AFEFEFEFEFEFEFEFEFEFEFEFEFEFEFEFEFEFEFEFEFEFEFEFFFEFEFEFEFEFEFEFEFEFEFEFEFEFEFEFEFEFEFEFEFEFEFEFEFEFEFEFEFEFEFEFEFEFEFEFEFEFEFEFEFEFEFEFEFEFEFEFEFEFEFEFE1401010101010101011E010A010101010101010101010101010101010101010101010101010101010101010101010101010101010101010101010101010101010A0A01010101010101010101010101011E010101010101010101010101010101010A010A01010A010101010A01010A0A0A0A01010A0A0A0A0A0A0A0A0A0101010101010101010101010A0A140A0A0A1E011E0101010101010A0A0A0A1E1E1E1E0A0A0A0A0A0A0A0A1E0A0A0A0A0A0A1E0A0A1E1E0A0A1E0A1E1E1E1E1E1E1E1E1E1E1E1E1E1E010101FFFF01010101010101010101010101010101010101010101010101010101010101010101010101010101010101010101010101010101010101010101010101010101010101010101010101010101010101010101010101010101010101010101010101010101010101010101010101010101011E1E0101010101010101010101010101010101140A0A1E0A0A0A0A0A0A010101010A0A0A01010101010101010A010101
A2: =IF(B2="","",TEXT(B2,"yyyymmdd")&"_"&TEXT(C2,"0000")) -> 20260123_0000 | B2: 46045 | C2: 0 | D2: =MID(I$1,$C2*2+1,2) -> 14 | E2: 0 | F2: =IF(C2="","",INT(C2/60)) -> 0 | G2: =IF(D2="","",IF(LEN(UPPER(SUBSTITUTE(SUBSTITUTE(TRIM(D2),CHAR(160),"")," ","")))=1,"0"&UPPER(SUBSTITUTE(SUBSTITUTE(TRIM(D2),CHAR(160),"")," ","")),UPPER(SUBSTITUTE(SUBSTITUTE(TRIM(D2),CHAR(160),"")," ","")))) -> 14
A3: =IF(B3="","",TEXT(B3,"yyyymmdd")&"_"&TEXT(C3,"0000")) -> 20260123_0001 | B3: 46045 | C3: 1 | D3: =MID(I$1,$C3*2+1,2) -> 00 | E3: 0 | F3: =IF(C3="","",INT(C3/60)) -> 0 | G3: =IF(D3="","",IF(LEN(UPPER(SUBSTITUTE(SUBSTITUTE(TRIM(D3),CHAR(160),"")," ","")))=1,"0"&UPPER(SUBSTITUTE(SUBSTITUTE(TRIM(D3),CHAR(160),"")," ","")),UPPER(SUBSTITUTE(SUBSTITUTE(TRIM(D3),CHAR(160),"")," ","")))) -> 00
A4: =IF(B4="","",TEXT(B4,"yyyymmdd")&"_"&TEXT(C4,"0000")) -> 20260123_0002 | B4: 46045 | C4: 2 | D4: =MID(I$1,$C4*2+1,2) -> 00 | E4: 0 | F4: =IF(C4="","",INT(C4/60)) -> 0 | G4: =IF(D4="","",IF(LEN(UPPER(SUBSTITUTE(SUBSTITUTE(TRIM(D4),CHAR(160),"")," ","")))=1,"0"&UPPER(SUBSTITUTE(SUBSTITUTE(TRIM(D4),CHAR(160),"")," ","")),UPPER(SUBSTITUTE(SUBSTITUTE(TRIM(D4),CHAR(160),"")," ","")))) -> 00
A5: =IF(B5="","",TEXT(B5,"yyyymmdd")&"_"&TEXT(C5,"0000")) -> 20260123_0003 | B5: 46045 | C5: 3 | D5: =MID(I$1,$C5*2+1,2) -> 00 | E5: 0 | F5: =IF(C5="","",INT(C5/60)) -> 0 | G5: =IF(D5="","",IF(LEN(UPPER(SUBSTITUTE(SUBSTITUTE(TRIM(D5),CHAR(160),"")," ","")))=1,"0"&UPPER(SUBSTITUTE(SUBSTITUTE(TRIM(D5),CHAR(160),"")," ","")),UPPER(SUBSTITUTE(SUBSTITUTE(TRIM(D5),CHAR(160),"")," ","")))) -> 00
A6: =IF(B6="","",TEXT(B6,"yyyymmdd")&"_"&TEXT(C6,"0000")) -> 20260123_0004 | B6: 46045 | C6: 4 | D6: =MID(I$1,$C6*2+1,2) -> 01 | E6: 0 | F6: =IF(C6="","",INT(C6/60)) -> 0 | G6: =IF(D6="","",IF(LEN(UPPER(SUBSTITUTE(SUBSTITUTE(TRIM(D6),CHAR(160),"")," ","")))=1,"0"&UPPER(SUBSTITUTE(SUBSTITUTE(TRIM(D6),CHAR(160),"")," ","")),UPPER(SUBSTITUTE(SUBSTITUTE(TRIM(D6),CHAR(160),"")," ","")))) -> 01
A7: =IF(B7="","",TEXT(B7,"yyyymmdd")&"_"&TEXT(C7,"0000")) -> 20260123_0005 | B7: 46045 | C7: 5 | D7: =MID(I$1,$C7*2+1,2) -> 01 | E7: 0 | F7: =IF(C7="","",INT(C7/60)) -> 0 | G7: =IF(D7="","",IF(LEN(UPPER(SUBSTITUTE(SUBSTITUTE(TRIM(D7),CHAR(160),"")," ","")))=1,"0"&UPPER(SUBSTITUTE(SUBSTITUTE(TRIM(D7),CHAR(160),"")," ","")),UPPER(SUBSTITUTE(SUBSTITUTE(TRIM(D7),CHAR(160),"")," ","")))) -> 01
A8: =IF(B8="","",TEXT(B8,"yyyymmdd")&"_"&TEXT(C8,"0000")) -> 20260123_0006 | B8: 46045 | C8: 6 | D8: =MID(I$1,$C8*2+1,2) -> 01 | E8: 0 | F8: =IF(C8="","",INT(C8/60)) -> 0 | G8: =IF(D8="","",IF(LEN(UPPER(SUBSTITUTE(SUBSTITUTE(TRIM(D8),CHAR(160),"")," ","")))=1,"0"&UPPER(SUBSTITUTE(SUBSTITUTE(TRIM(D8),CHAR(160),"")," ","")),UPPER(SUBSTITUTE(SUBSTITUTE(TRIM(D8),CHAR(160),"")," ","")))) -> 01
A9: =IF(B9="","",TEXT(B9,"yyyymmdd")&"_"&TEXT(C9,"0000")) -> 20260123_0007 | B9: 46045 | C9: 7 | D9: =MID(I$1,$C9*2+1,2) -> 01 | E9: 0 | F9: =IF(C9="","",INT(C9/60)) -> 0 | G9: =IF(D9="","",IF(LEN(UPPER(SUBSTITUTE(SUBSTITUTE(TRIM(D9),CHAR(160),"")," ","")))=1,"0"&UPPER(SUBSTITUTE(SUBSTITUTE(TRIM(D9),CHAR(160),"")," ","")),UPPER(SUBSTITUTE(SUBSTITUTE(TRIM(D9),CHAR(160),"")," ","")))) -> 01
A10: =IF(B10="","",TEXT(B10,"yyyymmdd")&"_"&TEXT(C10,"0000")) -> 20260123_0008 | B10: 46045 | C10: 8 | D10: =MID(I$1,$C10*2+1,2) -> 01 | E10: 0 | F10: =IF(C10="","",INT(C10/60)) -> 0 | G10: =IF(D10="","",IF(LEN(UPPER(SUBSTITUTE(SUBSTITUTE(TRIM(D10),CHAR(160),"")," ","")))=1,"0"&UPPER(SUBSTITUTE(SUBSTITUTE(TRIM(D10),CHAR(160),"")," ","")),UPPER(SUBSTITUTE(SUBSTITUTE(TRIM(D10),CHAR(160),"")," ","")))) -> 01
A11: =IF(B11="","",TEXT(B11,"yyyymmdd")&"_"&TEXT(C11,"0000")) -> 20260123_0009 | B11: 46045 | C11: 9 | D11: =MID(I$1,$C11*2+1,2) -> 01 | E11: 0 | F11: =IF(C11="","",INT(C11/60)) -> 0 | G11: =IF(D11="","",IF(LEN(UPPER(SUBSTITUTE(SUBSTITUTE(TRIM(D11),CHAR(160),"")," ","")))=1,"0"&UPPER(SUBSTITUTE(SUBSTITUTE(TRIM(D11),CHAR(160),"")," ","")),UPPER(SUBSTITUTE(SUBSTITUTE(TRIM(D11),CHAR(160),"")," ","")))) -> 01
A12: =IF(B12="","",TEXT(B12,"yyyymmdd")&"_"&TEXT(C12,"0000")) -> 20260123_0010 | B12: 46045 | C12: 10 | D12: =MID(I$1,$C12*2+1,2) -> 00 | E12: 0 | F12: =IF(C12="","",INT(C12/60)) -> 0 | G12: =IF(D12="","",IF(LEN(UPPER(SUBSTITUTE(SUBSTITUTE(TRIM(D12),CHAR(160),"")," ","")))=1,"0"&UPPER(SUBSTITUTE(SUBSTITUTE(TRIM(D12),CHAR(160),"")," ","")),UPPER(SUBSTITUTE(SUBSTITUTE(TRIM(D12),CHAR(160),"")," ","")))) -> 00
A13: =IF(B13="","",TEXT(B13,"yyyymmdd")&"_"&TEXT(C13,"0000")) -> 20260123_0011 | B13: 46045 | C13: 11 | D13: =MID(I$1,$C13*2+1,2) -> 00 | E13: 0 | F13: =IF(C13="","",INT(C13/60)) -> 0 | G13: =IF(D13="","",IF(LEN(UPPER(SUBSTITUTE(SUBSTITUTE(TRIM(D13),CHAR(160),"")," ","")))=1,"0"&UPPER(SUBSTITUTE(SUBSTITUTE(TRIM(D13),CHAR(160),"")," ","")),UPPER(SUBSTITUTE(SUBSTITUTE(TRIM(D13),CHAR(160),"")," ","")))) -> 00
... A1441: =IF(B1441="","",TEXT(B1441,"yyyymmdd")&"_"&TEXT(C1441,"0000")) -> 20260123_1439 | B1441: 46045 | C1441: 1439 | D1441: =MID(I$1,$C1441*2+1,2) -> 01 | E1441: 0 | F1441: =IF(C1441="","",INT(C1441/60)) -> 23 | G1441: =IF(D1441="","",IF(LEN(UPPER(SUBSTITUTE(SUBSTITUTE(TRIM(D1441),CHAR(160),"")," ","")))=1,"0"&UPPER(SUBSTITUTE(SUBSTITUTE(TRIM(D1441),CHAR(160),"")," ","")),UPPER(SUBSTITUTE(SUBSTITUTE(TRIM(D1441),CHAR(160),"")," ","")))) -> 01

Sheet DailyView
A1: 일자별 이동 대시보드
K2: 범례
A3: 선택 날짜 | B3: 46045 | K3: 침실A
A4: 총 이동거리 (m) | C4: 활동 분(거리>0) | E4: 외출 분 | G4: 방 이동 횟수 | K4: 침실B
A5: =IFERROR(SUMIFS(RawData!$E$2:$E$1441,RawData!$B$2:$B$1441,$B$3),0) -> 6.6887132 | C5: =IFERROR(COUNTIFS(RawData!$B$2:$B$1441,$B$3,RawData!$E$2:$E$1441,">0"),0) -> 272 | E5: =IFERROR(COUNTIFS(RawData!$B$2:$B$1441,$B$3,RawData!$D$2:$D$1441,"FE"),0) -> 199 | G5: =IFERROR(SUM($BN$11:$BN$1456),0) -> 165 | K5: 거실A
K6: 화장실
K7: 주방
K8: 외출
A10: 위치 타임라인 (1분 단위) | B10: Hour | C10: 0 | D10: 1 | E10: 2 | F10: 3 | G10: 4 | H10: 5 | I10: 6 | J10: 7 | K10: 8 | L10: 9 | M10: 10 | N10: 11 | O10: 12 | P10: 13 | Q10: 14 | R10: 15 | S10: 16 | T10: 17 | U10: 18 | V10: 19 | W10: 20 | X10: 21 | Y10: 22 | Z10: 23 | AA10: 24 | AB10: 25 | AC10: 26 | AD10: 27 | AE10: 28 | AF10: 29 | AG10: 30 | AH10: 31 | AI10: 32 | AJ10: 33 | AK10: 34 | AL10: 35 | AM10: 36 | AN10: 37 | AO10: 38 | AP10: 39 | AQ10: 40 | AR10: 41 | AS10: 42 | AT10: 43 | AU10: 44 | AV10: 45 | AW10: 46 | AX10: 47 | AY10: 48 | AZ10: 49 | BA10: 50 | BB10: 51 | BC10: 52 | BD10: 53 | BE10: 54 | BF10: 55 | BG10: 56 | BH10: 57 | BI10: 58 | BJ10: 59 | BK10: LocHex | BL10: Time | BM10: Distance_m | BN10: ChangeFlag
B11: 0 | C11: =IFERROR(VLOOKUP(TEXT($B$3,"yyyymmdd")&"_"&TEXT($B11*60+C$10,"0000"),RawData!$A$2:$G$30000,5,FALSE),"") -> 0 | D11: =IFERROR(VLOOKUP(TEXT($B$3,"yyyymmdd")&"_"&TEXT($B11*60+D$10,"0000"),RawData!$A$2:$G$30000,5,FALSE),"") -> 0 | E11: =IFERROR(VLOOKUP(TEXT($B$3,"yyyymmdd")&"_"&TEXT($B11*60+E$10,"0000"),RawData!$A$2:$G$30000,5,FALSE),"") -> 0 | F11: =IFERROR(VLOOKUP(TEXT($B$3,"yyyymmdd")&"_"&TEXT($B11*60+F$10,"0000"),RawData!$A$2:$G$30000,5,FALSE),"") -> 0 | G11: =IFERROR(VLOOKUP(TEXT($B$3,"yyyymmdd")&"_"&TEXT($B11*60+G$10,"0000"),RawData!$A$2:$G$30000,5,FALSE),"") -> 0 | H11: =IFERROR(VLOOKUP(TEXT($B$3,"yyyymmdd")&"_"&TEXT($B11*60+H$10,"0000"),RawData!$A$2:$G$30000,5,FALSE),"") -> 0 | I11: =IFERROR(VLOOKUP(TEXT($B$3,"yyyymmdd")&"_"&TEXT($B11*60+I$10,"0000"),RawData!$A$2:$G$30000,5,FALSE),"") -> 0 | J11: =IFERROR(VLOOKUP(TEXT($B$3,"yyyymmdd")&"_"&TEXT($B11*60+J$10,"0000"),RawData!$A$2:$G$30000,5,FALSE),"") -> 0 | ... BJ11: =IFERROR(VLOOKUP(TEXT($B$3,"yyyymmdd")&"_"&TEXT($B11*60+BJ$10,"0000"),RawData!$A$2:$G$30000,5,FALSE),"") -> 0 | BK11: =IFERROR(VLOOKUP(TEXT($B$3,"yyyymmdd")&"_"&TEXT(0,"0000"),RawData!$A$2:$F$1441,4,FALSE),"") -> 14 | BL11: =TIME(0,0,0)+0/1440 -> 0 | BM11: =IFERROR(VLOOKUP(TEXT($B$3,"yyyymmdd")&"_"&TEXT(0,"0000"),RawData!$A$2:$F$1441,5,FALSE),"") -> 0 | BN11: =0 -> 0
B12: 1 | C12: =IFERROR(VLOOKUP(TEXT($B$3,"yyyymmdd")&"_"&TEXT($B12*60+C$10,"0000"),RawData!$A$2:$G$30000,5,FALSE),"") -> 0 | D12: =IFERROR(VLOOKUP(TEXT($B$3,"yyyymmdd")&"_"&TEXT($B12*60+D$10,"0000"),RawData!$A$2:$G$30000,5,FALSE),"") -> 0 | E12: =IFERROR(VLOOKUP(TEXT($B$3,"yyyymmdd")&"_"&TEXT($B12*60+E$10,"0000"),RawData!$A$2:$G$30000,5,FALSE),"") -> 0 | F12: =IFERROR(VLOOKUP(TEXT($B$3,"yyyymmdd")&"_"&TEXT($B12*60+F$10,"0000"),RawData!$A$2:$G$30000,5,FALSE),"") -> 0 | G12: =IFERROR(VLOOKUP(TEXT($B$3,"yyyymmdd")&"_"&TEXT($B12*60+G$10,"0000"),RawData!$A$2:$G$30000,5,FALSE),"") -> 0 | H12: =IFERROR(VLOOKUP(TEXT($B$3,"yyyymmdd")&"_"&TEXT($B12*60+H$10,"0000"),RawData!$A$2:$G$30000,5,FALSE),"") -> 0 | I12: =IFERROR(VLOOKUP(TEXT($B$3,"yyyymmdd")&"_"&TEXT($B12*60+I$10,"0000"),RawData!$A$2:$G$30000,5,FALSE),"") -> 0 | J12: =IFERROR(VLOOKUP(TEXT($B$3,"yyyymmdd")&"_"&TEXT($B12*60+J$10,"0000"),RawData!$A$2:$G$30000,5,FALSE),"") -> 0 | ... BJ12: =IFERROR(VLOOKUP(TEXT($B$3,"yyyymmdd")&"_"&TEXT($B12*60+BJ$10,"0000"),RawData!$A$2:$G$30000,5,FALSE),"") -> 0 | BK12: =IFERROR(VLOOKUP(TEXT($B$3,"yyyymmdd")&"_"&TEXT(1,"0000"),RawData!$A$2:$F$1441,4,FALSE),"") -> 00 | BL12: =TIME(0,0,0)+1/1440 -> 0.00069444444 | BM12: =IFERROR(VLOOKUP(TEXT($B$3,"yyyymmdd")&"_"&TEXT(1,"0000"),RawData!$A$2:$F$1441,5,FALSE),"") -> 0 | BN12: =IF(BK12="","",IF(BK12<>BK11,1,0)) -> 1
B13: 2 | C13: =IFERROR(VLOOKUP(TEXT($B$3,"yyyymmdd")&"_"&TEXT($B13*60+C$10,"0000"),RawData!$A$2:$G$30000,5,FALSE),"") -> 0 | D13: =IFERROR(VLOOKUP(TEXT($B$3,"yyyymmdd")&"_"&TEXT($B13*60+D$10,"0000"),RawData!$A$2:$G$30000,5,FALSE),"") -> 0 | E13: =IFERROR(VLOOKUP(TEXT($B$3,"yyyymmdd")&"_"&TEXT($B13*60+E$10,"0000"),RawData!$A$2:$G$30000,5,FALSE),"") -> 0 | F13: =IFERROR(VLOOKUP(TEXT($B$3,"yyyymmdd")&"_"&TEXT($B13*60+F$10,"0000"),RawData!$A$2:$G$30000,5,FALSE),"") -> 0 | G13: =IFERROR(VLOOKUP(TEXT($B$3,"yyyymmdd")&"_"&TEXT($B13*60+G$10,"0000"),RawData!$A$2:$G$30000,5,FALSE),"") -> 0 | H13: =IFERROR(VLOOKUP(TEXT($B$3,"yyyymmdd")&"_"&TEXT($B13*60+H$10,"0000"),RawData!$A$2:$G$30000,5,FALSE),"") -> 0 | I13: =IFERROR(VLOOKUP(TEXT($B$3,"yyyymmdd")&"_"&TEXT($B13*60+I$10,"0000"),RawData!$A$2:$G$30000,5,FALSE),"") -> 0 | J13: =IFERROR(VLOOKUP(TEXT($B$3,"yyyymmdd")&"_"&TEXT($B13*60+J$10,"0000"),RawData!$A$2:$G$30000,5,FALSE),"") -> 0 | ... BJ13: =IFERROR(VLOOKUP(TEXT($B$3,"yyyymmdd")&"_"&TEXT($B13*60+BJ$10,"0000"),RawData!$A$2:$G$30000,5,FALSE),"") -> 0 | BK13: =IFERROR(VLOOKUP(TEXT($B$3,"yyyymmdd")&"_"&TEXT(2,"0000"),RawData!$A$2:$F$1441,4,FALSE),"") -> 00 | BL13: =TIME(0,0,0)+2/1440 -> 0.0013888889 | BM13: =IFERROR(VLOOKUP(TEXT($B$3,"yyyymmdd")&"_"&TEXT(2,"0000"),RawData!$A$2:$F$1441,5,FALSE),"") -> 0 | BN13: =IF(BK13="","",IF(BK13<>BK12,1,0)) -> 0
B14: 3 | C14: =IFERROR(VLOOKUP(TEXT($B$3,"yyyymmdd")&"_"&TEXT($B14*60+C$10,"0000"),RawData!$A$2:$G$30000,5,FALSE),"") -> 0 | D14: =IFERROR(VLOOKUP(TEXT($B$3,"yyyymmdd")&"_"&TEXT($B14*60+D$10,"0000"),RawData!$A$2:$G$30000,5,FALSE),"") -> 0 | E14: =IFERROR(VLOOKUP(TEXT($B$3,"yyyymmdd")&"_"&TEXT($B14*60+E$10,"0000"),RawData!$A$2:$G$30000,5,FALSE),"") -> 0 | F14: =IFERROR(VLOOKUP(TEXT($B$3,"yyyymmdd")&"_"&TEXT($B14*60+F$10,"0000"),RawData!$A$2:$G$30000,5,FALSE),"") -> 0 | G14: =IFERROR(VLOOKUP(TEXT($B$3,"yyyymmdd")&"_"&TEXT($B14*60+G$10,"0000"),RawData!$A$2:$G$30000,5,FALSE),"") -> 0 | H14: =IFERROR(VLOOKUP(TEXT($B$3,"yyyymmdd")&"_"&TEXT($B14*60+H$10,"0000"),RawData!$A$2:$G$30000,5,FALSE),"") -> 0 | I14: =IFERROR(VLOOKUP(TEXT($B$3,"yyyymmdd")&"_"&TEXT($B14*60+I$10,"0000"),RawData!$A$2:$G$30000,5,FALSE),"") -> 0 | J14: =IFERROR(VLOOKUP(TEXT($B$3,"yyyymmdd")&"_"&TEXT($B14*60+J$10,"0000"),RawData!$A$2:$G$30000,5,FALSE),"") -> 0 | ... BJ14: =IFERROR(VLOOKUP(TEXT($B$3,"yyyymmdd")&"_"&TEXT($B14*60+BJ$10,"0000"),RawData!$A$2:$G$30000,5,FALSE),"") -> 0 | BK14: =IFERROR(VLOOKUP(TEXT($B$3,"yyyymmdd")&"_"&TEXT(3,"0000"),RawData!$A$2:$F$1441,4,FALSE),"") -> 00 | BL14: =TIME(0,0,0)+3/1440 -> 0.0020833333 | BM14: =IFERROR(VLOOKUP(TEXT($B$3,"yyyymmdd")&"_"&TEXT(3,"0000"),RawData!$A$2:$F$1441,5,FALSE),"") -> 0 | BN14: =IF(BK14="","",IF(BK14<>BK13,1,0)) -> 0
B15: 4 | C15: =IFERROR(VLOOKUP(TEXT($B$3,"yyyymmdd")&"_"&TEXT($B15*60+C$10,"0000"),RawData!$A$2:$G$30000,5,FALSE),"") -> 0 | D15: =IFERROR(VLOOKUP(TEXT($B$3,"yyyymmdd")&"_"&TEXT($B15*60+D$10,"0000"),RawData!$A$2:$G$30000,5,FALSE),"") -> 0 | E15: =IFERROR(VLOOKUP(TEXT($B$3,"yyyymmdd")&"_"&TEXT($B15*60+E$10,"0000"),RawData!$A$2:$G$30000,5,FALSE),"") -> 0 | F15: =IFERROR(VLOOKUP(TEXT($B$3,"yyyymmdd")&"_"&TEXT($B15*60+F$10,"0000"),RawData!$A$2:$G$30000,5,FALSE),"") -> 0 | G15: =IFERROR(VLOOKUP(TEXT($B$3,"yyyymmdd")&"_"&TEXT($B15*60+G$10,"0000"),RawData!$A$2:$G$30000,5,FALSE),"") -> 0 | H15: =IFERROR(VLOOKUP(TEXT($B$3,"yyyymmdd")&"_"&TEXT($B15*60+H$10,"0000"),RawData!$A$2:$G$30000,5,FALSE),"") -> 0 | I15: =IFERROR(VLOOKUP(TEXT($B$3,"yyyymmdd")&"_"&TEXT($B15*60+I$10,"0000"),RawData!$A$2:$G$30000,5,FALSE),"") -> 0 | J15: =IFERROR(VLOOKUP(TEXT($B$3,"yyyymmdd")&"_"&TEXT($B15*60+J$10,"0000"),RawData!$A$2:$G$30000,5,FALSE),"") -> 0 | ... BJ15: =IFERROR(VLOOKUP(TEXT($B$3,"yyyymmdd")&"_"&TEXT($B15*60+BJ$10,"0000"),RawData!$A$2:$G$30000,5,FALSE),"") -> 0 | BK15: =IFERROR(VLOOKUP(TEXT($B$3,"yyyymmdd")&"_"&TEXT(4,"0000"),RawData!$A$2:$F$1441,4,FALSE),"") -> 01 | BL15: =TIME(0,0,0)+4/1440 -> 0.0027777778 | BM15: =IFERROR(VLOOKUP(TEXT($B$3,"yyyymmdd")&"_"&TEXT(4,"0000"),RawData!$A$2:$F$1441,5,FALSE),"") -> 0 | BN15: =IF(BK15="","",IF(BK15<>BK14,1,0)) -> 1
B16: 5 | C16: =IFERROR(VLOOKUP(TEXT($B$3,"yyyymmdd")&"_"&TEXT($B16*60+C$10,"0000"),RawData!$A$2:$G$30000,5,FALSE),"") -> 0 | D16: =IFERROR(VLOOKUP(TEXT($B$3,"yyyymmdd")&"_"&TEXT($B16*60+D$10,"0000"),RawData!$A$2:$G$30000,5,FALSE),"") -> 0 | E16: =IFERROR(VLOOKUP(TEXT($B$3,"yyyymmdd")&"_"&TEXT($B16*60+E$10,"0000"),RawData!$A$2:$G$30000,5,FALSE),"") -> 0 | F16: =IFERROR(VLOOKUP(TEXT($B$3,"yyyymmdd")&"_"&TEXT($B16*60+F$10,"0000"),RawData!$A$2:$G$30000,5,FALSE),"") -> 0 | G16: =IFERROR(VLOOKUP(TEXT($B$3,"yyyymmdd")&"_"&TEXT($B16*60+G$10,"0000"),RawData!$A$2:$G$30000,5,FALSE),"") -> 0 | H16: =IFERROR(VLOOKUP(TEXT($B$3,"yyyymmdd")&"_"&TEXT($B16*60+H$10,"0000"),RawData!$A$2:$G$30000,5,FALSE),"") -> 0 | I16: =IFERROR(VLOOKUP(TEXT($B$3,"yyyymmdd")&"_"&TEXT($B16*60+I$10,"0000"),RawData!$A$2:$G$30000,5,FALSE),"") -> 0 | J16: =IFERROR(VLOOKUP(TEXT($B$3,"yyyymmdd")&"_"&TEXT($B16*60+J$10,"0000"),RawData!$A$2:$G$30000,5,FALSE),"") -> 0 | ... BJ16: =IFERROR(VLOOKUP(TEXT($B$3,"yyyymmdd")&"_"&TEXT($B16*60+BJ$10,"0000"),RawData!$A$2:$G$30000,5,FALSE),"") -> 0 | BK16: =IFERROR(VLOOKUP(TEXT($B$3,"yyyymmdd")&"_"&TEXT(5,"0000"),RawData!$A$2:$F$1441,4,FALSE),"") -> 01 | BL16: =TIME(0,0,0)+5/1440 -> 0.0034722222 | BM16: =IFERROR(VLOOKUP(TEXT($B$3,"yyyymmdd")&"_"&TEXT(5,"0000"),RawData!$A$2:$F$1441,5,FALSE),"") -> 0 | BN16: =IF(BK16="","",IF(BK16<>BK15,1,0)) -> 0
B17: 6 | C17: =IFERROR(VLOOKUP(TEXT($B$3,"yyyymmdd")&"_"&TEXT($B17*60+C$10,"0000"),RawData!$A$2:$G$30000,5,FALSE),"") -> 0 | D17: =IFERROR(VLOOKUP(TEXT($B$3,"yyyymmdd")&"_"&TEXT($B17*60+D$10,"0000"),RawData!$A$2:$G$30000,5,FALSE),"") -> 0 | E17: =IFERROR(VLOOKUP(TEXT($B$3,"yyyymmdd")&"_"&TEXT($B17*60+E$10,"0000"),RawData!$A$2:$G$30000,5,FALSE),"") -> 0 | F17: =IFERROR(VLOOKUP(TEXT($B$3,"yyyymmdd")&"_"&TEXT($B17*60+F$10,"0000"),RawData!$A$2:$G$30000,5,FALSE),"") -> 0 | G17: =IFERROR(VLOOKUP(TEXT($B$3,"yyyymmdd")&"_"&TEXT($B17*60+G$10,"0000"),RawData!$A$2:$G$30000,5,FALSE),"") -> 0 | H17: =IFERROR(VLOOKUP(TEXT($B$3,"yyyymmdd")&"_"&TEXT($B17*60+H$10,"0000"),RawData!$A$2:$G$30000,5,FALSE),"") -> 0 | I17: =IFERROR(VLOOKUP(TEXT($B$3,"yyyymmdd")&"_"&TEXT($B17*60+I$10,"0000"),RawData!$A$2:$G$30000,5,FALSE),"") -> 0 | J17: =IFERROR(VLOOKUP(TEXT($B$3,"yyyymmdd")&"_"&TEXT($B17*60+J$10,"0000"),RawData!$A$2:$G$30000,5,FALSE),"") -> 0 | ... BJ17: =IFERROR(VLOOKUP(TEXT($B$3,"yyyymmdd")&"_"&TEXT($B17*60+BJ$10,"0000"),RawData!$A$2:$G$30000,5,FALSE),"") -> 0 | BK17: =IFERROR(VLOOKUP(TEXT($B$3,"yyyymmdd")&"_"&TEXT(6,"0000"),RawData!$A$2:$F$1441,4,FALSE),"") -> 01 | BL17: =TIME(0,0,0)+6/1440 -> 0.0041666667 | BM17: =IFERROR(VLOOKUP(TEXT($B$3,"yyyymmdd")&"_"&TEXT(6,"0000"),RawData!$A$2:$F$1441,5,FALSE),"") -> 0 | BN17: =IF(BK17="","",IF(BK17<>BK16,1,0)) -> 0
B18: 7 | C18: =IFERROR(VLOOKUP(TEXT($B$3,"yyyymmdd")&"_"&TEXT($B18*60+C$10,"0000"),RawData!$A$2:$G$30000,5,FALSE),"") -> 0 | D18: =IFERROR(VLOOKUP(TEXT($B$3,"yyyymmdd")&"_"&TEXT($B18*60+D$10,"0000"),RawData!$A$2:$G$30000,5,FALSE),"") -> 0 | E18: =IFERROR(VLOOKUP(TEXT($B$3,"yyyymmdd")&"_"&TEXT($B18*60+E$10,"0000"),RawData!$A$2:$G$30000,5,FALSE),"") -> 0 | F18: =IFERROR(VLOOKUP(TEXT($B$3,"yyyymmdd")&"_"&TEXT($B18*60+F$10,"0000"),RawData!$A$2:$G$30000,5,FALSE),"") -> 0 | G18: =IFERROR(VLOOKUP(TEXT($B$3,"yyyymmdd")&"_"&TEXT($B18*60+G$10,"0000"),RawData!$A$2:$G$30000,5,FALSE),"") -> 0 | H18: =IFERROR(VLOOKUP(TEXT($B$3,"yyyymmdd")&"_"&TEXT($B18*60+H$10,"0000"),RawData!$A$2:$G$30000,5,FALSE),"") -> 0 | I18: =IFERROR(VLOOKUP(TEXT($B$3,"yyyymmdd")&"_"&TEXT($B18*60+I$10,"0000"),RawData!$A$2:$G$30000,5,FALSE),"") -> 0 | J18: =IFERROR(VLOOKUP(TEXT($B$3,"yyyymmdd")&"_"&TEXT($B18*60+J$10,"0000"),RawData!$A$2:$G$30000,5,FALSE),"") -> 0 | ... BJ18: =IFERROR(VLOOKUP(TEXT($B$3,"yyyymmdd")&"_"&TEXT($B18*60+BJ$10,"0000"),RawData!$A$2:$G$30000,5,FALSE),"") -> 0 | BK18: =IFERROR(VLOOKUP(TEXT($B$3,"yyyymmdd")&"_"&TEXT(7,"0000"),RawData!$A$2:$F$1441,4,FALSE),"") -> 01 | BL18: =TIME(0,0,0)+7/1440 -> 0.0048611111 | BM18: =IFERROR(VLOOKUP(TEXT($B$3,"yyyymmdd")&"_"&TEXT(7,"0000"),RawData!$A$2:$F$1441,5,FALSE),"") -> 0 | BN18: =IF(BK18="","",IF(BK18<>BK17,1,0)) -> 0
B19: 8 | C19: =IFERROR(VLOOKUP(TEXT($B$3,"yyyymmdd")&"_"&TEXT($B19*60+C$10,"0000"),RawData!$A$2:$G$30000,5,FALSE),"") -> 0 | D19: =IFERROR(VLOOKUP(TEXT($B$3,"yyyymmdd")&"_"&TEXT($B19*60+D$10,"0000"),RawData!$A$2:$G$30000,5,FALSE),"") -> 0 | E19: =IFERROR(VLOOKUP(TEXT($B$3,"yyyymmdd")&"_"&TEXT($B19*60+E$10,"0000"),RawData!$A$2:$G$30000,5,FALSE),"") -> 0 | F19: =IFERROR(VLOOKUP(TEXT($B$3,"yyyymmdd")&"_"&TEXT($B19*60+F$10,"0000"),RawData!$A$2:$G$30000,5,FALSE),"") -> 0 | G19: =IFERROR(VLOOKUP(TEXT($B$3,"yyyymmdd")&"_"&TEXT($B19*60+G$10,"0000"),RawData!$A$2:$G$30000,5,FALSE),"") -> 0 | H19: =IFERROR(VLOOKUP(TEXT($B$3,"yyyymmdd")&"_"&TEXT($B19*60+H$10,"0000"),RawData!$A$2:$G$30000,5,FALSE),"") -> 0 | I19: =IFERROR(VLOOKUP(TEXT($B$3,"yyyymmdd")&"_"&TEXT($B19*60+I$10,"0000"),RawData!$A$2:$G$30000,5,FALSE),"") -> 0 | J19: =IFERROR(VLOOKUP(TEXT($B$3,"yyyymmdd")&"_"&TEXT($B19*60+J$10,"0000"),RawData!$A$2:$G$30000,5,FALSE),"") -> 0 | ... BJ19: =IFERROR(VLOOKUP(TEXT($B$3,"yyyymmdd")&"_"&TEXT($B19*60+BJ$10,"0000"),RawData!$A$2:$G$30000,5,FALSE),"") -> 0 | BK19: =IFERROR(VLOOKUP(TEXT($B$3,"yyyymmdd")&"_"&TEXT(8,"0000"),RawData!$A$2:$F$1441,4,FALSE),"") -> 01 | BL19: =TIME(0,0,0)+8/1440 -> 0.0055555556 | BM19: =IFERROR(VLOOKUP(TEXT($B$3,"yyyymmdd")&"_"&TEXT(8,"0000"),RawData!$A$2:$F$1441,5,FALSE),"") -> 0 | BN19: =IF(BK19="","",IF(BK19<>BK18,1,0)) -> 0
B20: 9 | C20: =IFERROR(VLOOKUP(TEXT($B$3,"yyyymmdd")&"_"&TEXT($B20*60+C$10,"0000"),RawData!$A$2:$G$30000,5,FALSE),"") -> 0 | D20: =IFERROR(VLOOKUP(TEXT($B$3,"yyyymmdd")&"_"&TEXT($B20*60+D$10,"0000"),RawData!$A$2:$G$30000,5,FALSE),"") -> 0 | E20: =IFERROR(VLOOKUP(TEXT($B$3,"yyyymmdd")&"_"&TEXT($B20*60+E$10,"0000"),RawData!$A$2:$G$30000,5,FALSE),"") -> 0 | F20: =IFERROR(VLOOKUP(TEXT($B$3,"yyyymmdd")&"_"&TEXT($B20*60+F$10,"0000"),RawData!$A$2:$G$30000,5,FALSE),"") -> 0 | G20: =IFERROR(VLOOKUP(TEXT($B$3,"yyyymmdd")&"_"&TEXT($B20*60+G$10,"0000"),RawData!$A$2:$G$30000,5,FALSE),"") -> 0 | H20: =IFERROR(VLOOKUP(TEXT($B$3,"yyyymmdd")&"_"&TEXT($B20*60+H$10,"0000"),RawData!$A$2:$G$30000,5,FALSE),"") -> 0 | I20: =IFERROR(VLOOKUP(TEXT($B$3,"yyyymmdd")&"_"&TEXT($B20*60+I$10,"0000"),RawData!$A$2:$G$30000,5,FALSE),"") -> 0 | J20: =IFERROR(VLOOKUP(TEXT($B$3,"yyyymmdd")&"_"&TEXT($B20*60+J$10,"0000"),RawData!$A$2:$G$30000,5,FALSE),"") -> 0 | ... BJ20: =IFERROR(VLOOKUP(TEXT($B$3,"yyyymmdd")&"_"&TEXT($B20*60+BJ$10,"0000"),RawData!$A$2:$G$30000,5,FALSE),"") -> 0 | BK20: =IFERROR(VLOOKUP(TEXT($B$3,"yyyymmdd")&"_"&TEXT(9,"0000"),RawData!$A$2:$F$1441,4,FALSE),"") -> 01 | BL20: =TIME(0,0,0)+9/1440 -> 0.00625 | BM20: =IFERROR(VLOOKUP(TEXT($B$3,"yyyymmdd")&"_"&TEXT(9,"0000"),RawData!$A$2:$F$1441,5,FALSE),"") -> 0 | BN20: =IF(BK20="","",IF(BK20<>BK19,1,0)) -> 0
B21: 10 | C21: =IFERROR(VLOOKUP(TEXT($B$3,"yyyymmdd")&"_"&TEXT($B21*60+C$10,"0000"),RawData!$A$2:$G$30000,5,FALSE),"") -> 0 | D21: =IFERROR(VLOOKUP(TEXT($B$3,"yyyymmdd")&"_"&TEXT($B21*60+D$10,"0000"),RawData!$A$2:$G$30000,5,FALSE),"") -> 0 | E21: =IFERROR(VLOOKUP(TEXT($B$3,"yyyymmdd")&"_"&TEXT($B21*60+E$10,"0000"),RawData!$A$2:$G$30000,5,FALSE),"") -> 0 | F21: =IFERROR(VLOOKUP(TEXT($B$3,"yyyymmdd")&"_"&TEXT($B21*60+F$10,"0000"),RawData!$A$2:$G$30000,5,FALSE),"") -> 0 | G21: =IFERROR(VLOOKUP(TEXT($B$3,"yyyymmdd")&"_"&TEXT($B21*60+G$10,"0000"),RawData!$A$2:$G$30000,5,FALSE),"") -> 0 | H21: =IFERROR(VLOOKUP(TEXT($B$3,"yyyymmdd")&"_"&TEXT($B21*60+H$10,"0000"),RawData!$A$2:$G$30000,5,FALSE),"") -> 0 | I21: =IFERROR(VLOOKUP(TEXT($B$3,"yyyymmdd")&"_"&TEXT($B21*60+I$10,"0000"),RawData!$A$2:$G$30000,5,FALSE),"") -> 0 | J21: =IFERROR(VLOOKUP(TEXT($B$3,"yyyymmdd")&"_"&TEXT($B21*60+J$10,"0000"),RawData!$A$2:$G$30000,5,FALSE),"") -> 0 | ... BJ21: =IFERROR(VLOOKUP(TEXT($B$3,"yyyymmdd")&"_"&TEXT($B21*60+BJ$10,"0000"),RawData!$A$2:$G$30000,5,FALSE),"") -> 0 | BK21: =IFERROR(VLOOKUP(TEXT($B$3,"yyyymmdd")&"_"&TEXT(10,"0000"),RawData!$A$2:$F$1441,4,FALSE),"") -> 00 | BL21: =TIME(0,0,0)+10/1440 -> 0.0069444444 | BM21: =IFERROR(VLOOKUP(TEXT($B$3,"yyyymmdd")&"_"&TEXT(10,"0000"),RawData!$A$2:$F$1441,5,FALSE),"") -> 0 | BN21: =IF(BK21="","",IF(BK21<>BK20,1,0)) -> 1
B22: 11 | C22: =IFERROR(VLOOKUP(TEXT($B$3,"yyyymmdd")&"_"&TEXT($B22*60+C$10,"0000"),RawData!$A$2:$G$30000,5,FALSE),"") -> 0 | D22: =IFERROR(VLOOKUP(TEXT($B$3,"yyyymmdd")&"_"&TEXT($B22*60+D$10,"0000"),RawData!$A$2:$G$30000,5,FALSE),"") -> 0 | E22: =IFERROR(VLOOKUP(TEXT($B$3,"yyyymmdd")&"_"&TEXT($B22*60+E$10,"0000"),RawData!$A$2:$G$30000,5,FALSE),"") -> 0 | F22: =IFERROR(VLOOKUP(TEXT($B$3,"yyyymmdd")&"_"&TEXT($B22*60+F$10,"0000"),RawData!$A$2:$G$30000,5,FALSE),"") -> 0 | G22: =IFERROR(VLOOKUP(TEXT($B$3,"yyyymmdd")&"_"&TEXT($B22*60+G$10,"0000"),RawData!$A$2:$G$30000,5,FALSE),"") -> 0 | H22: =IFERROR(VLOOKUP(TEXT($B$3,"yyyymmdd")&"_"&TEXT($B22*60+H$10,"0000"),RawData!$A$2:$G$30000,5,FALSE),"") -> 0 | I22: =IFERROR(VLOOKUP(TEXT($B$3,"yyyymmdd")&"_"&TEXT($B22*60+I$10,"0000"),RawData!$A$2:$G$30000,5,FALSE),"") -> 0 | J22: =IFERROR(VLOOKUP(TEXT($B$3,"yyyymmdd")&"_"&TEXT($B22*60+J$10,"0000"),RawData!$A$2:$G$30000,5,FALSE),"") -> 0 | ... BJ22: =IFERROR(VLOOKUP(TEXT($B$3,"yyyymmdd")&"_"&TEXT($B22*60+BJ$10,"0000"),RawData!$A$2:$G$30000,5,FALSE),"") -> 0 | BK22: =IFERROR(VLOOKUP(TEXT($B$3,"yyyymmdd")&"_"&TEXT(11,"0000"),RawData!$A$2:$F$1441,4,FALSE),"") -> 00 | BL22: =TIME(0,0,0)+11/1440 -> 0.0076388889 | BM22: =IFERROR(VLOOKUP(TEXT($B$3,"yyyymmdd")&"_"&TEXT(11,"0000"),RawData!$A$2:$F$1441,5,FALSE),"") -> 0 | BN22: =IF(BK22="","",IF(BK22<>BK21,1,0)) -> 0
B23: 12 | C23: =IFERROR(VLOOKUP(TEXT($B$3,"yyyymmdd")&"_"&TEXT($B23*60+C$10,"0000"),RawData!$A$2:$G$30000,5,FALSE),"") -> 0.000412 | D23: =IFERROR(VLOOKUP(TEXT($B$3,"yyyymmdd")&"_"&TEXT($B23*60+D$10,"0000"),RawData!$A$2:$G$30000,5,FALSE),"") -> 0 | E23: =IFERROR(VLOOKUP(TEXT($B$3,"yyyymmdd")&"_"&TEXT($B23*60+E$10,"0000"),RawData!$A$2:$G$30000,5,FALSE),"") -> 0 | F23: =IFERROR(VLOOKUP(TEXT($B$3,"yyyymmdd")&"_"&TEXT($B23*60+F$10,"0000"),RawData!$A$2:$G$30000,5,FALSE),"") -> 0 | G23: =IFERROR(VLOOKUP(TEXT($B$3,"yyyymmdd")&"_"&TEXT($B23*60+G$10,"0000"),RawData!$A$2:$G$30000,5,FALSE),"") -> 0 | H23: =IFERROR(VLOOKUP(TEXT($B$3,"yyyymmdd")&"_"&TEXT($B23*60+H$10,"0000"),RawData!$A$2:$G$30000,5,FALSE),"") -> 0 | I23: =IFERROR(VLOOKUP(TEXT($B$3,"yyyymmdd")&"_"&TEXT($B23*60+I$10,"0000"),RawData!$A$2:$G$30000,5,FALSE),"") -> 0 | J23: =IFERROR(VLOOKUP(TEXT($B$3,"yyyymmdd")&"_"&TEXT($B23*60+J$10,"0000"),RawData!$A$2:$G$30000,5,FALSE),"") -> 0.000567 | ... BJ23: =IFERROR(VLOOKUP(TEXT($B$3,"yyyymmdd")&"_"&TEXT($B23*60+BJ$10,"0000"),RawData!$A$2:$G$30000,5,FALSE),"") -> 0 | BK23: =IFERROR(VLOOKUP(TEXT($B$3,"yyyymmdd")&"_"&TEXT(12,"0000"),RawData!$A$2:$F$1441,4,FALSE),"") -> 00 | BL23: =TIME(0,0,0)+12/1440 -> 0.0083333333 | BM23: =IFERROR(VLOOKUP(TEXT($B$3,"yyyymmdd")&"_"&TEXT(12,"0000"),RawData!$A$2:$F$1441,5,FALSE),"") -> 0 | BN23: =IF(BK23="","",IF(BK23<>BK22,1,0)) -> 0
B24: 13 | C24: =IFERROR(VLOOKUP(TEXT($B$3,"yyyymmdd")&"_"&TEXT($B24*60+C$10,"0000"),RawData!$A$2:$G$30000,5,FALSE),"") -> 0 | D24: =IFERROR(VLOOKUP(TEXT($B$3,"yyyymmdd")&"_"&TEXT($B24*60+D$10,"0000"),RawData!$A$2:$G$30000,5,FALSE),"") -> 0 | E24: =IFERROR(VLOOKUP(TEXT($B$3,"yyyymmdd")&"_"&TEXT($B24*60+E$10,"0000"),RawData!$A$2:$G$30000,5,FALSE),"") -> 0 | F24: =IFERROR(VLOOKUP(TEXT($B$3,"yyyymmdd")&"_"&TEXT($B24*60+F$10,"0000"),RawData!$A$2:$G$30000,5,FALSE),"") -> 0.000263 | G24: =IFERROR(VLOOKUP(TEXT($B$3,"yyyymmdd")&"_"&TEXT($B24*60+G$10,"0000"),RawData!$A$2:$G$30000,5,FALSE),"") -> 0 | H24: =IFERROR(VLOOKUP(TEXT($B$3,"yyyymmdd")&"_"&TEXT($B24*60+H$10,"0000"),RawData!$A$2:$G$30000,5,FALSE),"") -> 0 | I24: =IFERROR(VLOOKUP(TEXT($B$3,"yyyymmdd")&"_"&TEXT($B24*60+I$10,"0000"),RawData!$A$2:$G$30000,5,FALSE),"") -> 0 | J24: =IFERROR(VLOOKUP(TEXT($B$3,"yyyymmdd")&"_"&TEXT($B24*60+J$10,"0000"),RawData!$A$2:$G$30000,5,FALSE),"") -> 0 | ... BJ24: =IFERROR(VLOOKUP(TEXT($B$3,"yyyymmdd")&"_"&TEXT($B24*60+BJ$10,"0000"),RawData!$A$2:$G$30000,5,FALSE),"") -> 0 | BK24: =IFERROR(VLOOKUP(TEXT($B$3,"yyyymmdd")&"_"&TEXT(13,"0000"),RawData!$A$2:$F$1441,4,FALSE),"") -> 01 | BL24: =TIME(0,0,0)+13/1440 -> 0.0090277778 | BM24: =IFERROR(VLOOKUP(TEXT($B$3,"yyyymmdd")&"_"&TEXT(13,"0000"),RawData!$A$2:$F$1441,5,FALSE),"") -> 0 | BN24: =IF(BK24="","",IF(BK24<>BK23,1,0)) -> 1
B25: 14 | C25: =IFERROR(VLOOKUP(TEXT($B$3,"yyyymmdd")&"_"&TEXT($B25*60+C$10,"0000"),RawData!$A$2:$G$30000,5,FALSE),"") -> 0 | D25: =IFERROR(VLOOKUP(TEXT($B$3,"yyyymmdd")&"_"&TEXT($B25*60+D$10,"0000"),RawData!$A$2:$G$30000,5,FALSE),"") -> 0 | E25: =IFERROR(VLOOKUP(TEXT($B$3,"yyyymmdd")&"_"&TEXT($B25*60+E$10,"0000"),RawData!$A$2:$G$30000,5,FALSE),"") -> 0 | F25: =IFERROR(VLOOKUP(TEXT($B$3,"yyyymmdd")&"_"&TEXT($B25*60+F$10,"0000"),RawData!$A$2:$G$30000,5,FALSE),"") -> 0 | G25: =IFERROR(VLOOKUP(TEXT($B$3,"yyyymmdd")&"_"&TEXT($B25*60+G$10,"0000"),RawData!$A$2:$G$30000,5,FALSE),"") -> 0 | H25: =IFERROR(VLOOKUP(TEXT($B$3,"yyyymmdd")&"_"&TEXT($B25*60+H$10,"0000"),RawData!$A$2:$G$30000,5,FALSE),"") -> 0 | I25: =IFERROR(VLOOKUP(TEXT($B$3,"yyyymmdd")&"_"&TEXT($B25*60+I$10,"0000"),RawData!$A$2:$G$30000,5,FALSE),"") -> 0 | J25: =IFERROR(VLOOKUP(TEXT($B$3,"yyyymmdd")&"_"&TEXT($B25*60+J$10,"0000"),RawData!$A$2:$G$30000,5,FALSE),"") -> 0 | ... BJ25: =IFERROR(VLOOKUP(TEXT($B$3,"yyyymmdd")&"_"&TEXT($B25*60+BJ$10,"0000"),RawData!$A$2:$G$30000,5,FALSE),"") -> 0 | BK25: =IFERROR(VLOOKUP(TEXT($B$3,"yyyymmdd")&"_"&TEXT(14,"0000"),RawData!$A$2:$F$1441,4,FALSE),"") -> 01 | BL25: =TIME(0,0,0)+14/1440 -> 0.0097222222 | BM25: =IFERROR(VLOOKUP(TEXT($B$3,"yyyymmdd")&"_"&TEXT(14,"0000"),RawData!$A$2:$F$1441,5,FALSE),"") -> 0 | BN25: =IF(BK25="","",IF(BK25<>BK24,1,0)) -> 0
B26: 15 | C26: =IFERROR(VLOOKUP(TEXT($B$3,"yyyymmdd")&"_"&TEXT($B26*60+C$10,"0000"),RawData!$A$2:$G$30000,5,FALSE),"") -> 0 | D26: =IFERROR(VLOOKUP(TEXT($B$3,"yyyymmdd")&"_"&TEXT($B26*60+D$10,"0000"),RawData!$A$2:$G$30000,5,FALSE),"") -> 0 | E26: =IFERROR(VLOOKUP(TEXT($B$3,"yyyymmdd")&"_"&TEXT($B26*60+E$10,"0000"),RawData!$A$2:$G$30000,5,FALSE),"") -> 0 | F26: =IFERROR(VLOOKUP(TEXT($B$3,"yyyymmdd")&"_"&TEXT($B26*60+F$10,"0000"),RawData!$A$2:$G$30000,5,FALSE),"") -> 0 | G26: =IFERROR(VLOOKUP(TEXT($B$3,"yyyymmdd")&"_"&TEXT($B26*60+G$10,"0000"),RawData!$A$2:$G$30000,5,FALSE),"") -> 0 | H26: =IFERROR(VLOOKUP(TEXT($B$3,"yyyymmdd")&"_"&TEXT($B26*60+H$10,"0000"),RawData!$A$2:$G$30000,5,FALSE),"") -> 0 | I26: =IFERROR(VLOOKUP(TEXT($B$3,"yyyymmdd")&"_"&TEXT($B26*60+I$10,"0000"),RawData!$A$2:$G$30000,5,FALSE),"") -> 0 | J26: =IFERROR(VLOOKUP(TEXT($B$3,"yyyymmdd")&"_"&TEXT($B26*60+J$10,"0000"),RawData!$A$2:$G$30000,5,FALSE),"") -> 0 | ... BJ26: =IFERROR(VLOOKUP(TEXT($B$3,"yyyymmdd")&"_"&TEXT($B26*60+BJ$10,"0000"),RawData!$A$2:$G$30000,5,FALSE),"") -> 0 | BK26: =IFERROR(VLOOKUP(TEXT($B$3,"yyyymmdd")&"_"&TEXT(15,"0000"),RawData!$A$2:$F$1441,4,FALSE),"") -> 01 | BL26: =TIME(0,0,0)+15/1440 -> 0.010416667 | BM26: =IFERROR(VLOOKUP(TEXT($B$3,"yyyymmdd")&"_"&TEXT(15,"0000"),RawData!$A$2:$F$1441,5,FALSE),"") -> 0 | BN26: =IF(BK26="","",IF(BK26<>BK25,1,0)) -> 0
B27: 16 | C27: =IFERROR(VLOOKUP(TEXT($B$3,"yyyymmdd")&"_"&TEXT($B27*60+C$10,"0000"),RawData!$A$2:$G$30000,5,FALSE),"") -> 0 | D27: =IFERROR(VLOOKUP(TEXT($B$3,"yyyymmdd")&"_"&TEXT($B27*60+D$10,"0000"),RawData!$A$2:$G$30000,5,FALSE),"") -> 0 | E27: =IFERROR(VLOOKUP(TEXT($B$3,"yyyymmdd")&"_"&TEXT($B27*60+E$10,"0000"),RawData!$A$2:$G$30000,5,FALSE),"") -> 0.000336 | F27: =IFERROR(VLOOKUP(TEXT($B$3,"yyyymmdd")&"_"&TEXT($B27*60+F$10,"0000"),RawData!$A$2:$G$30000,5,FALSE),"") -> 0.000511 | G27: =IFERROR(VLOOKUP(TEXT($B$3,"yyyymmdd")&"_"&TEXT($B27*60+G$10,"0000"),RawData!$A$2:$G$30000,5,FALSE),"") -> 0 | H27: =IFERROR(VLOOKUP(TEXT($B$3,"yyyymmdd")&"_"&TEXT($B27*60+H$10,"0000"),RawData!$A$2:$G$30000,5,FALSE),"") -> 0 | I27: =IFERROR(VLOOKUP(TEXT($B$3,"yyyymmdd")&"_"&TEXT($B27*60+I$10,"0000"),RawData!$A$2:$G$30000,5,FALSE),"") -> 0.000534 | J27: =IFERROR(VLOOKUP(TEXT($B$3,"yyyymmdd")&"_"&TEXT($B27*60+J$10,"0000"),RawData!$A$2:$G$30000,5,FALSE),"") -> 0.000357 | ... BJ27: =IFERROR(VLOOKUP(TEXT($B$3,"yyyymmdd")&"_"&TEXT($B27*60+BJ$10,"0000"),RawData!$A$2:$G$30000,5,FALSE),"") -> 0 | BK27: =IFERROR(VLOOKUP(TEXT($B$3,"yyyymmdd")&"_"&TEXT(16,"0000"),RawData!$A$2:$F$1441,4,FALSE),"") -> 01 | BL27: =TIME(0,0,0)+16/1440 -> 0.011111111 | BM27: =IFERROR(VLOOKUP(TEXT($B$3,"yyyymmdd")&"_"&TEXT(16,"0000"),RawData!$A$2:$F$1441,5,FALSE),"") -> 0 | BN27: =IF(BK27="","",IF(BK27<>BK26,1,0)) -> 0
B28: 17 | C28: =IFERROR(VLOOKUP(TEXT($B$3,"yyyymmdd")&"_"&TEXT($B28*60+C$10,"0000"),RawData!$A$2:$G$30000,5,FALSE),"") -> 0.000756 | D28: =IFERROR(VLOOKUP(TEXT($B$3,"yyyymmdd")&"_"&TEXT($B28*60+D$10,"0000"),RawData!$A$2:$G$30000,5,FALSE),"") -> 0.000441 | E28: =IFERROR(VLOOKUP(TEXT($B$3,"yyyymmdd")&"_"&TEXT($B28*60+E$10,"0000"),RawData!$A$2:$G$30000,5,FALSE),"") -> 0 | F28: =IFERROR(VLOOKUP(TEXT($B$3,"yyyymmdd")&"_"&TEXT($B28*60+F$10,"0000"),RawData!$A$2:$G$30000,5,FALSE),"") -> 0 | G28: =IFERROR(VLOOKUP(TEXT($B$3,"yyyymmdd")&"_"&TEXT($B28*60+G$10,"0000"),RawData!$A$2:$G$30000,5,FALSE),"") -> 0 | H28: =IFERROR(VLOOKUP(TEXT($B$3,"yyyymmdd")&"_"&TEXT($B28*60+H$10,"0000"),RawData!$A$2:$G$30000,5,FALSE),"") -> 0 | I28: =IFERROR(VLOOKUP(TEXT($B$3,"yyyymmdd")&"_"&TEXT($B28*60+I$10,"0000"),RawData!$A$2:$G$30000,5,FALSE),"") -> 0 | J28: =IFERROR(VLOOKUP(TEXT($B$3,"yyyymmdd")&"_"&TEXT($B28*60+J$10,"0000"),RawData!$A$2:$G$30000,5,FALSE),"") -> 0.000238 | ... BJ28: =IFERROR(VLOOKUP(TEXT($B$3,"yyyymmdd")&"_"&TEXT($B28*60+BJ$10,"0000"),RawData!$A$2:$G$30000,5,FALSE),"") -> 0.000498 | BK28: =IFERROR(VLOOKUP(TEXT($B$3,"yyyymmdd")&"_"&TEXT(17,"0000"),RawData!$A$2:$F$1441,4,FALSE),"") -> 01 | BL28: =TIME(0,0,0)+17/1440 -> 0.011805556 | BM28: =IFERROR(VLOOKUP(TEXT($B$3,"yyyymmdd")&"_"&TEXT(17,"0000"),RawData!$A$2:$F$1441,5,FALSE),"") -> 0 | BN28: =IF(BK28="","",IF(BK28<>BK27,1,0)) -> 0
B29: 18 | C29: =IFERROR(VLOOKUP(TEXT($B$3,"yyyymmdd")&"_"&TEXT($B29*60+C$10,"0000"),RawData!$A$2:$G$30000,5,FALSE),"") -> 0 | D29: =IFERROR(VLOOKUP(TEXT($B$3,"yyyymmdd")&"_"&TEXT($B29*60+D$10,"0000"),RawData!$A$2:$G$30000,5,FALSE),"") -> 0.000478 | E29: =IFERROR(VLOOKUP(TEXT($B$3,"yyyymmdd")&"_"&TEXT($B29*60+E$10,"0000"),RawData!$A$2:$G$30000,5,FALSE),"") -> 0 | F29: =IFERROR(VLOOKUP(TEXT($B$3,"yyyymmdd")&"_"&TEXT($B29*60+F$10,"0000"),RawData!$A$2:$G$30000,5,FALSE),"") -> 0 | G29: =IFERROR(VLOOKUP(TEXT($B$3,"yyyymmdd")&"_"&TEXT($B29*60+G$10,"0000"),RawData!$A$2:$G$30000,5,FALSE),"") -> 0.000343 | H29: =IFERROR(VLOOKUP(TEXT($B$3,"yyyymmdd")&"_"&TEXT($B29*60+H$10,"0000"),RawData!$A$2:$G$30000,5,FALSE),"") -> 0.000391 | I29: =IFERROR(VLOOKUP(TEXT($B$3,"yyyymmdd")&"_"&TEXT($B29*60+I$10,"0000"),RawData!$A$2:$G$30000,5,FALSE),"") -> 0 | J29: =IFERROR(VLOOKUP(TEXT($B$3,"yyyymmdd")&"_"&TEXT($B29*60+J$10,"0000"),RawData!$A$2:$G$30000,5,FALSE),"") -> 0.000899 | ... BJ29: =IFERROR(VLOOKUP(TEXT($B$3,"yyyymmdd")&"_"&TEXT($B29*60+BJ$10,"0000"),RawData!$A$2:$G$30000,5,FALSE),"") -> 0 | BK29: =IFERROR(VLOOKUP(TEXT($B$3,"yyyymmdd")&"_"&TEXT(18,"0000"),RawData!$A$2:$F$1441,4,FALSE),"") -> 01 | BL29: =TIME(0,0,0)+18/1440 -> 0.0125 | BM29: =IFERROR(VLOOKUP(TEXT($B$3,"yyyymmdd")&"_"&TEXT(18,"0000"),RawData!$A$2:$F$1441,5,FALSE),"") -> 0 | BN29: =IF(BK29="","",IF(BK29<>BK28,1,0)) -> 0
B30: 19 | C30: =IFERROR(VLOOKUP(TEXT($B$3,"yyyymmdd")&"_"&TEXT($B30*60+C$10,"0000"),RawData!$A$2:$G$30000,5,FALSE),"") -> 0 | D30: =IFERROR(VLOOKUP(TEXT($B$3,"yyyymmdd")&"_"&TEXT($B30*60+D$10,"0000"),RawData!$A$2:$G$30000,5,FALSE),"") -> 0 | E30: =IFERROR(VLOOKUP(TEXT($B$3,"yyyymmdd")&"_"&TEXT($B30*60+E$10,"0000"),RawData!$A$2:$G$30000,5,FALSE),"") -> 0.000479 | F30: =IFERROR(VLOOKUP(TEXT($B$3,"yyyymmdd")&"_"&TEXT($B30*60+F$10,"0000"),RawData!$A$2:$G$30000,5,FALSE),"") -> 0 | G30: =IFERROR(VLOOKUP(TEXT($B$3,"yyyymmdd")&"_"&TEXT($B30*60+G$10,"0000"),RawData!$A$2:$G$30000,5,FALSE),"") -> 0.000246 | H30: =IFERROR(VLOOKUP(TEXT($B$3,"yyyymmdd")&"_"&TEXT($B30*60+H$10,"0000"),RawData!$A$2:$G$30000,5,FALSE),"") -> 0.000443 | I30: =IFERROR(VLOOKUP(TEXT($B$3,"yyyymmdd")&"_"&TEXT($B30*60+I$10,"0000"),RawData!$A$2:$G$30000,5,FALSE),"") -> 0.000264 | J30: =IFERROR(VLOOKUP(TEXT($B$3,"yyyymmdd")&"_"&TEXT($B30*60+J$10,"0000"),RawData!$A$2:$G$30000,5,FALSE),"") -> 0.000362 | ... BJ30: =IFERROR(VLOOKUP(TEXT($B$3,"yyyymmdd")&"_"&TEXT($B30*60+BJ$10,"0000"),RawData!$A$2:$G$30000,5,FALSE),"") -> 0.000377 | BK30: =IFERROR(VLOOKUP(TEXT($B$3,"yyyymmdd")&"_"&TEXT(19,"0000"),RawData!$A$2:$F$1441,4,FALSE),"") -> 01 | BL30: =TIME(0,0,0)+19/1440 -> 0.013194444 | BM30: =IFERROR(VLOOKUP(TEXT($B$3,"yyyymmdd")&"_"&TEXT(19,"0000"),RawData!$A$2:$F$1441,5,FALSE),"") -> 0 | BN30: =IF(BK30="","",IF(BK30<>BK25,1,0)) -> 0
B31: 20 | C31: =IFERROR(VLOOKUP(TEXT($B$3,"yyyymmdd")&"_"&TEXT($B31*60+C$10,"0000"),RawData!$A$2:$G$30000,5,FALSE),"") -> 0 | D31: =IFERROR(VLOOKUP(TEXT($B$3,"yyyymmdd")&"_"&TEXT($B31*60+D$10,"0000"),RawData!$A$2:$G$30000,5,FALSE),"") -> 0 | E31: =IFERROR(VLOOKUP(TEXT($B$3,"yyyymmdd")&"_"&TEXT($B31*60+E$10,"0000"),RawData!$A$2:$G$30000,5,FALSE),"") -> 0 | F31: =IFERROR(VLOOKUP(TEXT($B$3,"yyyymmdd")&"_"&TEXT($B31*60+F$10,"0000"),RawData!$A$2:$G$30000,5,FALSE),"") -> 0 | G31: =IFERROR(VLOOKUP(TEXT($B$3,"yyyymmdd")&"_"&TEXT($B31*60+G$10,"0000"),RawData!$A$2:$G$30000,5,FALSE),"") -> 0.000371 | H31: =IFERROR(VLOOKUP(TEXT($B$3,"yyyymmdd")&"_"&TEXT($B31*60+H$10,"0000"),RawData!$A$2:$G$30000,5,FALSE),"") -> 0 | I31: =IFERROR(VLOOKUP(TEXT($B$3,"yyyymmdd")&"_"&TEXT($B31*60+I$10,"0000"),RawData!$A$2:$G$30000,5,FALSE),"") -> 0.000178 | J31: =IFERROR(VLOOKUP(TEXT($B$3,"yyyymmdd")&"_"&TEXT($B31*60+J$10,"0000"),RawData!$A$2:$G$30000,5,FALSE),"") -> 0.000401 | ... BJ31: =IFERROR(VLOOKUP(TEXT($B$3,"yyyymmdd")&"_"&TEXT($B31*60+BJ$10,"0000"),RawData!$A$2:$G$30000,5,FALSE),"") -> 0.000375 | BK31: =IFERROR(VLOOKUP(TEXT($B$3,"yyyymmdd")&"_"&TEXT(20,"0000"),RawData!$A$2:$F$1441,4,FALSE),"") -> 01 | BL31: =TIME(0,0,0)+20/1440 -> 0.013888889 | BM31: =IFERROR(VLOOKUP(TEXT($B$3,"yyyymmdd")&"_"&TEXT(20,"0000"),RawData!$A$2:$F$1441,5,FALSE),"") -> 0 | BN31: =IF(BK31="","",IF(BK31<>BK26,1,0)) -> 0
B32: 21 | C32: =IFERROR(VLOOKUP(TEXT($B$3,"yyyymmdd")&"_"&TEXT($B32*60+C$10,"0000"),RawData!$A$2:$G$30000,5,FALSE),"") -> 0 | D32: =IFERROR(VLOOKUP(TEXT($B$3,"yyyymmdd")&"_"&TEXT($B32*60+D$10,"0000"),RawData!$A$2:$G$30000,5,FALSE),"") -> 0 | E32: =IFERROR(VLOOKUP(TEXT($B$3,"yyyymmdd")&"_"&TEXT($B32*60+E$10,"0000"),RawData!$A$2:$G$30000,5,FALSE),"") -> 0 | F32: =IFERROR(VLOOKUP(TEXT($B$3,"yyyymmdd")&"_"&TEXT($B32*60+F$10,"0000"),RawData!$A$2:$G$30000,5,FALSE),"") -> 0.000813 | G32: =IFERROR(VLOOKUP(TEXT($B$3,"yyyymmdd")&"_"&TEXT($B32*60+G$10,"0000"),RawData!$A$2:$G$30000,5,FALSE),"") -> 0 | H32: =IFERROR(VLOOKUP(TEXT($B$3,"yyyymmdd")&"_"&TEXT($B32*60+H$10,"0000"),RawData!$A$2:$G$30000,5,FALSE),"") -> 0 | I32: =IFERROR(VLOOKUP(TEXT($B$3,"yyyymmdd")&"_"&TEXT($B32*60+I$10,"0000"),RawData!$A$2:$G$30000,5,FALSE),"") -> 0 | J32: =IFERROR(VLOOKUP(TEXT($B$3,"yyyymmdd")&"_"&TEXT($B32*60+J$10,"0000"),RawData!$A$2:$G$30000,5,FALSE),"") -> 0.070408213 | ... BJ32: =IFERROR(VLOOKUP(TEXT($B$3,"yyyymmdd")&"_"&TEXT($B32*60+BJ$10,"0000"),RawData!$A$2:$G$30000,5,FALSE),"") -> 0 | BK32: =IFERROR(VLOOKUP(TEXT($B$3,"yyyymmdd")&"_"&TEXT(21,"0000"),RawData!$A$2:$F$1441,4,FALSE),"") -> 01 | BL32: =TIME(0,0,0)+21/1440 -> 0.014583333 | BM32: =IFERROR(VLOOKUP(TEXT($B$3,"yyyymmdd")&"_"&TEXT(21,"0000"),RawData!$A$2:$F$1441,5,FALSE),"") -> 0 | BN32: =IF(BK32="","",IF(BK32<>BK27,1,0)) -> 0
B33: 22 | C33: =IFERROR(VLOOKUP(TEXT($B$3,"yyyymmdd")&"_"&TEXT($B33*60+C$10,"0000"),RawData!$A$2:$G$30000,5,FALSE),"") -> 0.000497 | D33: =IFERROR(VLOOKUP(TEXT($B$3,"yyyymmdd")&"_"&TEXT($B33*60+D$10,"0000"),RawData!$A$2:$G$30000,5,FALSE),"") -> 0.000257 | E33: =IFERROR(VLOOKUP(TEXT($B$3,"yyyymmdd")&"_"&TEXT($B33*60+E$10,"0000"),RawData!$A$2:$G$30000,5,FALSE),"") -> 0 | F33: =IFERROR(VLOOKUP(TEXT($B$3,"yyyymmdd")&"_"&TEXT($B33*60+F$10,"0000"),RawData!$A$2:$G$30000,5,FALSE),"") -> 0 | G33: =IFERROR(VLOOKUP(TEXT($B$3,"yyyymmdd")&"_"&TEXT($B33*60+G$10,"0000"),RawData!$A$2:$G$30000,5,FALSE),"") -> 0 | H33: =IFERROR(VLOOKUP(TEXT($B$3,"yyyymmdd")&"_"&TEXT($B33*60+H$10,"0000"),RawData!$A$2:$G$30000,5,FALSE),"") -> 0 | I33: =IFERROR(VLOOKUP(TEXT($B$3,"yyyymmdd")&"_"&TEXT($B33*60+I$10,"0000"),RawData!$A$2:$G$30000,5,FALSE),"") -> 0.000588 | J33: =IFERROR(VLOOKUP(TEXT($B$3,"yyyymmdd")&"_"&TEXT($B33*60+J$10,"0000"),RawData!$A$2:$G$30000,5,FALSE),"") -> 0 | ... BJ33: =IFERROR(VLOOKUP(TEXT($B$3,"yyyymmdd")&"_"&TEXT($B33*60+BJ$10,"0000"),RawData!$A$2:$G$30000,5,FALSE),"") -> 0.00055 | BK33: =IFERROR(VLOOKUP(TEXT($B$3,"yyyymmdd")&"_"&TEXT(22,"0000"),RawData!$A$2:$F$1441,4,FALSE),"") -> 01 | BL33: =TIME(0,0,0)+22/1440 -> 0.015277778 | BM33: =IFERROR(VLOOKUP(TEXT($B$3,"yyyymmdd")&"_"&TEXT(22,"0000"),RawData!$A$2:$F$1441,5,FALSE),"") -> 0 | BN33: =IF(BK33="","",IF(BK33<>BK28,1,0)) -> 0
B34: 23 | C34: =IFERROR(VLOOKUP(TEXT($B$3,"yyyymmdd")&"_"&TEXT($B34*60+C$10,"0000"),RawData!$A$2:$G$30000,5,FALSE),"") -> 0 | D34: =IFERROR(VLOOKUP(TEXT($B$3,"yyyymmdd")&"_"&TEXT($B34*60+D$10,"0000"),RawData!$A$2:$G$30000,5,FALSE),"") -> 0 | E34: =IFERROR(VLOOKUP(TEXT($B$3,"yyyymmdd")&"_"&TEXT($B34*60+E$10,"0000"),RawData!$A$2:$G$30000,5,FALSE),"") -> 0 | F34: =IFERROR(VLOOKUP(TEXT($B$3,"yyyymmdd")&"_"&TEXT($B34*60+F$10,"0000"),RawData!$A$2:$G$30000,5,FALSE),"") -> 0 | G34: =IFERROR(VLOOKUP(TEXT($B$3,"yyyymmdd")&"_"&TEXT($B34*60+G$10,"0000"),RawData!$A$2:$G$30000,5,FALSE),"") -> 0 | H34: =IFERROR(VLOOKUP(TEXT($B$3,"yyyymmdd")&"_"&TEXT($B34*60+H$10,"0000"),RawData!$A$2:$G$30000,5,FALSE),"") -> 0 | I34: =IFERROR(VLOOKUP(TEXT($B$3,"yyyymmdd")&"_"&TEXT($B34*60+I$10,"0000"),RawData!$A$2:$G$30000,5,FALSE),"") -> 0.000589 | J34: =IFERROR(VLOOKUP(TEXT($B$3,"yyyymmdd")&"_"&TEXT($B34*60+J$10,"0000"),RawData!$A$2:$G$30000,5,FALSE),"") -> 0 | ... BJ34: =IFERROR(VLOOKUP(TEXT($B$3,"yyyymmdd")&"_"&TEXT($B34*60+BJ$10,"0000"),RawData!$A$2:$G$30000,5,FALSE),"") -> 0 | BK34: =IFERROR(VLOOKUP(TEXT($B$3,"yyyymmdd")&"_"&TEXT(23,"0000"),RawData!$A$2:$F$1441,4,FALSE),"") -> 01 | BL34: =TIME(0,0,0)+23/1440 -> 0.015972222 | BM34: =IFERROR(VLOOKUP(TEXT($B$3,"yyyymmdd")&"_"&TEXT(23,"0000"),RawData!$A$2:$F$1441,5,FALSE),"") -> 0 | BN34: =IF(BK34="","",IF(BK34<>BK29,1,0)) -> 0
BK35: =IFERROR(VLOOKUP(TEXT($B$3,"yyyymmdd")&"_"&TEXT(24,"0000"),RawData!$A$2:$F$1441,4,FALSE),"") -> 01 | BL35: =TIME(0,0,0)+24/1440 -> 0.016666667 | BM35: =IFERROR(VLOOKUP(TEXT($B$3,"yyyymmdd")&"_"&TEXT(24,"0000"),RawData!$A$2:$F$1441,5,FALSE),"") -> 0 | BN35: =IF(BK35="","",IF(BK35<>BK30,1,0)) -> 0
A36: 시간대별 이동거리(합계) | BK36: =IFERROR(VLOOKUP(TEXT($B$3,"yyyymmdd")&"_"&TEXT(25,"0000"),RawData!$A$2:$F$1441,4,FALSE),"") -> 01 | BL36: =TIME(0,0,0)+25/1440 -> 0.017361111 | BM36: =IFERROR(VLOOKUP(TEXT($B$3,"yyyymmdd")&"_"&TEXT(25,"0000"),RawData!$A$2:$F$1441,5,FALSE),"") -> 0 | BN36: =IF(BK36="","",IF(BK36<>BK31,1,0)) -> 0
A37: Hour | B37: Distance_m | G37: =IFERROR(VLOOKUP(VLOOKUP(TEXT($B$3,"yyyymmdd")&"_"&TEXT($B37*60+4,"0000"),RawData!$A$2:$F$1441,4,FALSE),Mapping!$A$4:$B$9,2,FALSE),"") | H37: =IFERROR(VLOOKUP(VLOOKUP(TEXT($B$3,"yyyymmdd")&"_"&TEXT($B37*60+5,"0000"),RawData!$A$2:$F$1441,4,FALSE),Mapping!$A$4:$B$9,2,FALSE),"") | I37: =IFERROR(VLOOKUP(VLOOKUP(TEXT($B$3,"yyyymmdd")&"_"&TEXT($B37*60+6,"0000"),RawData!$A$2:$F$1441,4,FALSE),Mapping!$A$4:$B$9,2,FALSE),"") | J37: =IFERROR(VLOOKUP(VLOOKUP(TEXT($B$3,"yyyymmdd")&"_"&TEXT($B37*60+7,"0000"),RawData!$A$2:$F$1441,4,FALSE),Mapping!$A$4:$B$9,2,FALSE),"") | K37: =IFERROR(VLOOKUP(VLOOKUP(TEXT($B$3,"yyyymmdd")&"_"&TEXT($B37*60+8,"0000"),RawData!$A$2:$F$1441,4,FALSE),Mapping!$A$4:$B$9,2,FALSE),"") | L37: =IFERROR(VLOOKUP(VLOOKUP(TEXT($B$3,"yyyymmdd")&"_"&TEXT($B37*60+9,"0000"),RawData!$A$2:$F$1441,4,FALSE),Mapping!$A$4:$B$9,2,FALSE),"") | M37: =IFERROR(VLOOKUP(VLOOKUP(TEXT($B$3,"yyyymmdd")&"_"&TEXT($B37*60+10,"0000"),RawData!$A$2:$F$1441,4,FALSE),Mapping!$A$4:$B$9,2,FALSE),"") | N37: =IFERROR(VLOOKUP(VLOOKUP(TEXT($B$3,"yyyymmdd")&"_"&TEXT($B37*60+11,"0000"),RawData!$A$2:$F$1441,4,FALSE),Mapping!$A$4:$B$9,2,FALSE),"") | O37: =IFERROR(VLOOKUP(VLOOKUP(TEXT($B$3,"yyyymmdd")&"_"&TEXT($B37*60+12,"0000"),RawData!$A$2:$F$1441,4,FALSE),Mapping!$A$4:$B$9,2,FALSE),"") | P37: =IFERROR(VLOOKUP(VLOOKUP(TEXT($B$3,"yyyymmdd")&"_"&TEXT($B37*60+13,"0000"),RawData!$A$2:$F$1441,4,FALSE),Mapping!$A$4:$B$9,2,FALSE),"") | Q37: =IFERROR(VLOOKUP(VLOOKUP(TEXT($B$3,"yyyymmdd")&"_"&TEXT($B37*60+14,"0000"),RawData!$A$2:$F$1441,4,FALSE),Mapping!$A$4:$B$9,2,FALSE),"") | R37: =IFERROR(VLOOKUP(VLOOKUP(TEXT($B$3,"yyyymmdd")&"_"&TEXT($B37*60+15,"0000"),RawData!$A$2:$F$1441,4,FALSE),Mapping!$A$4:$B$9,2,FALSE),"") | S37: =IFERROR(VLOOKUP(VLOOKUP(TEXT($B$3,"yyyymmdd")&"_"&TEXT($B37*60+16,"0000"),RawData!$A$2:$F$1441,4,FALSE),Mapping!$A$4:$B$9,2,FALSE),"") | T37: =IFERROR(VLOOKUP(VLOOKUP(TEXT($B$3,"yyyymmdd")&"_"&TEXT($B37*60+17,"0000"),RawData!$A$2:$F$1441,4,FALSE),Mapping!$A$4:$B$9,2,FALSE),"") | U37: =IFERROR(VLOOKUP(VLOOKUP(TEXT($B$3,"yyyymmdd")&"_"&TEXT($B37*60+18,"0000"),RawData!$A$2:$F$1441,4,FALSE),Mapping!$A$4:$B$9,2,FALSE),"") | V37: =IFERROR(VLOOKUP(VLOOKUP(TEXT($B$3,"yyyymmdd")&"_"&TEXT($B37*60+19,"0000"),RawData!$A$2:$F$1441,4,FALSE),Mapping!$A$4:$B$9,2,FALSE),"") | W37: =IFERROR(VLOOKUP(VLOOKUP(TEXT($B$3,"yyyymmdd")&"_"&TEXT($B37*60+20,"0000"),RawData!$A$2:$F$1441,4,FALSE),Mapping!$A$4:$B$9,2,FALSE),"") | X37: =IFERROR(VLOOKUP(VLOOKUP(TEXT($B$3,"yyyymmdd")&"_"&TEXT($B37*60+21,"0000"),RawData!$A$2:$F$1441,4,FALSE),Mapping!$A$4:$B$9,2,FALSE),"") | Y37: =IFERROR(VLOOKUP(VLOOKUP(TEXT($B$3,"yyyymmdd")&"_"&TEXT($B37*60+22,"0000"),RawData!$A$2:$F$1441,4,FALSE),Mapping!$A$4:$B$9,2,FALSE),"") | Z37: =IFERROR(VLOOKUP(VLOOKUP(TEXT($B$3,"yyyymmdd")&"_"&TEXT($B37*60+23,"0000"),RawData!$A$2:$F$1441,4,FALSE),Mapping!$A$4:$B$9,2,FALSE),"") | AA37: =IFERROR(VLOOKUP(VLOOKUP(TEXT($B$3,"yyyymmdd")&"_"&TEXT($B37*60+24,"0000"),RawData!$A$2:$F$1441,4,FALSE),Mapping!$A$4:$B$9,2,FALSE),"") | AB37: =IFERROR(VLOOKUP(VLOOKUP(TEXT($B$3,"yyyymmdd")&"_"&TEXT($B37*60+25,"0000"),RawData!$A$2:$F$1441,4,FALSE),Mapping!$A$4:$B$9,2,FALSE),"") | AC37: =IFERROR(VLOOKUP(VLOOKUP(TEXT($B$3,"yyyymmdd")&"_"&TEXT($B37*60+26,"0000"),RawData!$A$2:$F$1441,4,FALSE),Mapping!$A$4:$B$9,2,FALSE),"") | AD37: =IFERROR(VLOOKUP(VLOOKUP(TEXT($B$3,"yyyymmdd")&"_"&TEXT($B37*60+27,"0000"),RawData!$A$2:$F$1441,4,FALSE),Mapping!$A$4:$B$9,2,FALSE),"") | AE37: =IFERROR(VLOOKUP(VLOOKUP(TEXT($B$3,"yyyymmdd")&"_"&TEXT($B37*60+28,"0000"),RawData!$A$2:$F$1441,4,FALSE),Mapping!$A$4:$B$9,2,FALSE),"") | AF37: =IFERROR(VLOOKUP(VLOOKUP(TEXT($B$3,"yyyymmdd")&"_"&TEXT($B37*60+29,"0000"),RawData!$A$2:$F$1441,4,FALSE),Mapping!$A$4:$B$9,2,FALSE),"") | AG37: =IFERROR(VLOOKUP(VLOOKUP(TEXT($B$3,"yyyymmdd")&"_"&TEXT($B37*60+30,"0000"),RawData!$A$2:$F$1441,4,FALSE),Mapping!$A$4:$B$9,2,FALSE),"") | AH37: =IFERROR(VLOOKUP(VLOOKUP(TEXT($B$3,"yyyymmdd")&"_"&TEXT($B37*60+31,"0000"),RawData!$A$2:$F$1441,4,FALSE),Mapping!$A$4:$B$9,2,FALSE),"") | AI37: =IFERROR(VLOOKUP(VLOOKUP(TEXT($B$3,"yyyymmdd")&"_"&TEXT($B37*60+32,"0000"),RawData!$A$2:$F$1441,4,FALSE),Mapping!$A$4:$B$9,2,FALSE),"") | AJ37: =IFERROR(VLOOKUP(VLOOKUP(TEXT($B$3,"yyyymmdd")&"_"&TEXT($B37*60+33,"0000"),RawData!$A$2:$F$1441,4,FALSE),Mapping!$A$4:$B$9,2,FALSE),"") | AK37: =IFERROR(VLOOKUP(VLOOKUP(TEXT($B$3,"yyyymmdd")&"_"&TEXT($B37*60+34,"0000"),RawData!$A$2:$F$1441,4,FALSE),Mapping!$A$4:$B$9,2,FALSE),"") | AL37: =IFERROR(VLOOKUP(VLOOKUP(TEXT($B$3,"yyyymmdd")&"_"&TEXT($B37*60+35,"0000"),RawData!$A$2:$F$1441,4,FALSE),Mapping!$A$4:$B$9,2,FALSE),"") | AM37: =IFERROR(VLOOKUP(VLOOKUP(TEXT($B$3,"yyyymmdd")&"_"&TEXT($B37*60+36,"0000"),RawData!$A$2:$F$1441,4,FALSE),Mapping!$A$4:$B$9,2,FALSE),"") | AN37: =IFERROR(VLOOKUP(VLOOKUP(TEXT($B$3,"yyyymmdd")&"_"&TEXT($B37*60+37,"0000"),RawData!$A$2:$F$1441,4,FALSE),Mapping!$A$4:$B$9,2,FALSE),"") | AO37: =IFERROR(VLOOKUP(VLOOKUP(TEXT($B$3,"yyyymmdd")&"_"&TEXT($B37*60+38,"0000"),RawData!$A$2:$F$1441,4,FALSE),Mapping!$A$4:$B$9,2,FALSE),"") | AP37: =IFERROR(VLOOKUP(VLOOKUP(TEXT($B$3,"yyyymmdd")&"_"&TEXT($B37*60+39,"0000"),RawData!$A$2:$F$1441,4,FALSE),Mapping!$A$4:$B$9,2,FALSE),"") | AQ37: =IFERROR(VLOOKUP(VLOOKUP(TEXT($B$3,"yyyymmdd")&"_"&TEXT($B37*60+40,"0000"),RawData!$A$2:$F$1441,4,FALSE),Mapping!$A$4:$B$9,2,FALSE),"") | AR37: =IFERROR(VLOOKUP(VLOOKUP(TEXT($B$3,"yyyymmdd")&"_"&TEXT($B37*60+41,"0000"),RawData!$A$2:$F$1441,4,FALSE),Mapping!$A$4:$B$9,2,FALSE),"") | AS37: =IFERROR(VLOOKUP(VLOOKUP(TEXT($B$3,"yyyymmdd")&"_"&TEXT($B37*60+42,"0000"),RawData!$A$2:$F$1441,4,FALSE),Mapping!$A$4:$B$9,2,FALSE),"") | AT37: =IFERROR(VLOOKUP(VLOOKUP(TEXT($B$3,"yyyymmdd")&"_"&TEXT($B37*60+43,"0000"),RawData!$A$2:$F$1441,4,FALSE),Mapping!$A$4:$B$9,2,FALSE),"") | AU37: =IFERROR(VLOOKUP(VLOOKUP(TEXT($B$3,"yyyymmdd")&"_"&TEXT($B37*60+44,"0000"),RawData!$A$2:$F$1441,4,FALSE),Mapping!$A$4:$B$9,2,FALSE),"") | AV37: =IFERROR(VLOOKUP(VLOOKUP(TEXT($B$3,"yyyymmdd")&"_"&TEXT($B37*60+45,"0000"),RawData!$A$2:$F$1441,4,FALSE),Mapping!$A$4:$B$9,2,FALSE),"") | AW37: =IFERROR(VLOOKUP(VLOOKUP(TEXT($B$3,"yyyymmdd")&"_"&TEXT($B37*60+46,"0000"),RawData!$A$2:$F$1441,4,FALSE),Mapping!$A$4:$B$9,2,FALSE),"") | AX37: =IFERROR(VLOOKUP(VLOOKUP(TEXT($B$3,"yyyymmdd")&"_"&TEXT($B37*60+47,"0000"),RawData!$A$2:$F$1441,4,FALSE),Mapping!$A$4:$B$9,2,FALSE),"") | AY37: =IFERROR(VLOOKUP(VLOOKUP(TEXT($B$3,"yyyymmdd")&"_"&TEXT($B37*60+48,"0000"),RawData!$A$2:$F$1441,4,FALSE),Mapping!$A$4:$B$9,2,FALSE),"") | AZ37: =IFERROR(VLOOKUP(VLOOKUP(TEXT($B$3,"yyyymmdd")&"_"&TEXT($B37*60+49,"0000"),RawData!$A$2:$F$1441,4,FALSE),Mapping!$A$4:$B$9,2,FALSE),"") | BA37: =IFERROR(VLOOKUP(VLOOKUP(TEXT($B$3,"yyyymmdd")&"_"&TEXT($B37*60+50,"0000"),RawData!$A$2:$F$1441,4,FALSE),Mapping!$A$4:$B$9,2,FALSE),"") | BB37: =IFERROR(VLOOKUP(VLOOKUP(TEXT($B$3,"yyyymmdd")&"_"&TEXT($B37*60+51,"0000"),RawData!$A$2:$F$1441,4,FALSE),Mapping!$A$4:$B$9,2,FALSE),"") | BC37: =IFERROR(VLOOKUP(VLOOKUP(TEXT($B$3,"yyyymmdd")&"_"&TEXT($B37*60+52,"0000"),RawData!$A$2:$F$1441,4,FALSE),Mapping!$A$4:$B$9,2,FALSE),"") | BD37: =IFERROR(VLOOKUP(VLOOKUP(TEXT($B$3,"yyyymmdd")&"_"&TEXT($B37*60+53,"0000"),RawData!$A$2:$F$1441,4,FALSE),Mapping!$A$4:$B$9,2,FALSE),"") | BE37: =IFERROR(VLOOKUP(VLOOKUP(TEXT($B$3,"yyyymmdd")&"_"&TEXT($B37*60+54,"0000"),RawData!$A$2:$F$1441,4,FALSE),Mapping!$A$4:$B$9,2,FALSE),"") | BF37: =IFERROR(VLOOKUP(VLOOKUP(TEXT($B$3,"yyyymmdd")&"_"&TEXT($B37*60+55,"0000"),RawData!$A$2:$F$1441,4,FALSE),Mapping!$A$4:$B$9,2,FALSE),"") | BG37: =IFERROR(VLOOKUP(VLOOKUP(TEXT($B$3,"yyyymmdd")&"_"&TEXT($B37*60+56,"0000"),RawData!$A$2:$F$1441,4,FALSE),Mapping!$A$4:$B$9,2,FALSE),"") | BH37: =IFERROR(VLOOKUP(VLOOKUP(TEXT($B$3,"yyyymmdd")&"_"&TEXT($B37*60+57,"0000"),RawData!$A$2:$F$1441,4,FALSE),Mapping!$A$4:$B$9,2,FALSE),"") | BI37: =IFERROR(VLOOKUP(VLOOKUP(TEXT($B$3,"yyyymmdd")&"_"&TEXT($B37*60+58,"0000"),RawData!$A$2:$F$1441,4,FALSE),Mapping!$A$4:$B$9,2,FALSE),"") | BJ37: =IFERROR(VLOOKUP(VLOOKUP(TEXT($B$3,"yyyymmdd")&"_"&TEXT($B37*60+59,"0000"),RawData!$A$2:$F$1441,4,FALSE),Mapping!$A$4:$B$9,2,FALSE),"") | BK37: =IFERROR(VLOOKUP(TEXT($B$3,"yyyymmdd")&"_"&TEXT(26,"0000"),RawData!$A$2:$F$1441,4,FALSE),"") -> 01 | BL37: =TIME(0,0,0)+26/1440 -> 0.018055556 | BM37: =IFERROR(VLOOKUP(TEXT($B$3,"yyyymmdd")&"_"&TEXT(26,"0000"),RawData!$A$2:$F$1441,5,FALSE),"") -> 0 | BN37: =IF(BK37="","",IF(BK37<>BK32,1,0)) -> 0
A38: 0 | B38: =IFERROR(SUMIFS(RawData!$E$2:$E$1441,RawData!$B$2:$B$1441,$B$3,RawData!$F$2:$F$1441,0),0) -> 0 | BK38: =IFERROR(VLOOKUP(TEXT($B$3,"yyyymmdd")&"_"&TEXT(27,"0000"),RawData!$A$2:$F$1441,4,FALSE),"") -> 01 | BL38: =TIME(0,0,0)+27/1440 -> 0.01875 | BM38: =IFERROR(VLOOKUP(TEXT($B$3,"yyyymmdd")&"_"&TEXT(27,"0000"),RawData!$A$2:$F$1441,5,FALSE),"") -> 0 | BN38: =IF(BK38="","",IF(BK38<>BK33,1,0)) -> 0
A39: 1 | B39: =IFERROR(SUMIFS(RawData!$E$2:$E$1441,RawData!$B$2:$B$1441,$B$3,RawData!$F$2:$F$1441,1),0) -> 0 | BK39: =IFERROR(VLOOKUP(TEXT($B$3,"yyyymmdd")&"_"&TEXT(28,"0000"),RawData!$A$2:$F$1441,4,FALSE),"") -> 1E | BL39: =TIME(0,0,0)+28/1440 -> 0.019444444 | BM39: =IFERROR(VLOOKUP(TEXT($B$3,"yyyymmdd")&"_"&TEXT(28,"0000"),RawData!$A$2:$F$1441,5,FALSE),"") -> 0 | BN39: =IF(BK39="","",IF(BK39<>BK34,1,0)) -> 1
A40: 2 | B40: =IFERROR(SUMIFS(RawData!$E$2:$E$1441,RawData!$B$2:$B$1441,$B$3,RawData!$F$2:$F$1441,2),0) -> 0 | S40: =IFERROR(VLOOKUP(VLOOKUP(TEXT($B$3,"yyyymmdd")&"_"&TEXT($B40*60+16,"0000"),RawData!$A$2:$F$1441,4,FALSE),Mapping!$A$4:$B$9,2,FALSE),"") -> 침실B | T40: =IFERROR(VLOOKUP(VLOOKUP(TEXT($B$3,"yyyymmdd")&"_"&TEXT($B40*60+17,"0000"),RawData!$A$2:$F$1441,4,FALSE),Mapping!$A$4:$B$9,2,FALSE),"") -> 침실B | U40: =IFERROR(VLOOKUP(VLOOKUP(TEXT($B$3,"yyyymmdd")&"_"&TEXT($B40*60+18,"0000"),RawData!$A$2:$F$1441,4,FALSE),Mapping!$A$4:$B$9,2,FALSE),"") -> 침실B | V40: =IFERROR(VLOOKUP(VLOOKUP(TEXT($B$3,"yyyymmdd")&"_"&TEXT($B40*60+19,"0000"),RawData!$A$2:$F$1441,4,FALSE),Mapping!$A$4:$B$9,2,FALSE),"") -> 침실B | W40: =IFERROR(VLOOKUP(VLOOKUP(TEXT($B$3,"yyyymmdd")&"_"&TEXT($B40*60+20,"0000"),RawData!$A$2:$F$1441,4,FALSE),Mapping!$A$4:$B$9,2,FALSE),"") -> 침실B | X40: =IFERROR(VLOOKUP(VLOOKUP(TEXT($B$3,"yyyymmdd")&"_"&TEXT($B40*60+21,"0000"),RawData!$A$2:$F$1441,4,FALSE),Mapping!$A$4:$B$9,2,FALSE),"") -> 침실B | Y40: =IFERROR(VLOOKUP(VLOOKUP(TEXT($B$3,"yyyymmdd")&"_"&TEXT($B40*60+22,"0000"),RawData!$A$2:$F$1441,4,FALSE),Mapping!$A$4:$B$9,2,FALSE),"") -> 침실B | Z40: =IFERROR(VLOOKUP(VLOOKUP(TEXT($B$3,"yyyymmdd")&"_"&TEXT($B40*60+23,"0000"),RawData!$A$2:$F$1441,4,FALSE),Mapping!$A$4:$B$9,2,FALSE),"") -> 침실B | AA40: =IFERROR(VLOOKUP(VLOOKUP(TEXT($B$3,"yyyymmdd")&"_"&TEXT($B40*60+24,"0000"),RawData!$A$2:$F$1441,4,FALSE),Mapping!$A$4:$B$9,2,FALSE),"") -> 침실B | BK40: =IFERROR(VLOOKUP(TEXT($B$3,"yyyymmdd")&"_"&TEXT(29,"0000"),RawData!$A$2:$F$1441,4,FALSE),"") -> 00 | BL40: =TIME(0,0,0)+29/1440 -> 0.020138889 | BM40: =IFERROR(VLOOKUP(TEXT($B$3,"yyyymmdd")&"_"&TEXT(29,"0000"),RawData!$A$2:$F$1441,5,FALSE),"") -> 0 | BN40: =IF(BK40="","",IF(BK40<>BK35,1,0)) -> 1
A41: 3 | B41: =IFERROR(SUMIFS(RawData!$E$2:$E$1441,RawData!$B$2:$B$1441,$B$3,RawData!$F$2:$F$1441,3),0) -> 0 | BK41: =IFERROR(VLOOKUP(TEXT($B$3,"yyyymmdd")&"_"&TEXT(30,"0000"),RawData!$A$2:$F$1441,4,FALSE),"") -> 01 | BL41: =TIME(0,0,0)+30/1440 -> 0.020833333 | BM41: =IFERROR(VLOOKUP(TEXT($B$3,"yyyymmdd")&"_"&TEXT(30,"0000"),RawData!$A$2:$F$1441,5,FALSE),"") -> 0 | BN41: =IF(BK41="","",IF(BK41<>BK36,1,0)) -> 0
...
